#VRML_SIM R2023b utf8

EXTERNPROTO "webots://projects/objects/backgrounds/protos/TexturedBackgroundLight.proto"
EXTERNPROTO "webots://projects/objects/backgrounds/protos/TexturedBackground.proto"
EXTERNPROTO "webots://projects/objects/floors/protos/Floor.proto"

WorldInfo {
  basicTimeStep 1
  FPS 30
  lineScale 0.3
  contactProperties [
    ContactProperties {
      coulombFriction [
        0.4
      ]
    }
  ]
}
Viewpoint {
  orientation 0.12074167413191408 0.059104495176372396 -0.9909228561183604 2.2383300575133243
  position 1.8188650340799961 2.106276866159285 1.2491055642039575
  follow "T1_release"
}
TexturedBackground {
  texture "empty_office"
}
TexturedBackgroundLight {
}
Floor {
  size 200 200
  tileSize 1 1
}
Robot {
  translation 0 0 0.676
  children [
    Accelerometer {
      name "torso accelerometer"
    }
    GPS {
      name "torso gps"
    }
    Gyro {
      name "torso gyro"
    }
    InertialUnit {
      name "torso inertial unit"
    }
    Shape {
      appearance DEF Trunk_material PBRAppearance {
        baseColor 0.76 0.76 0.76
        roughness 1
        metalness 0
      }
      geometry DEF Trunk Mesh {
        url [
          "./T1_release_meshes_7Dof/Trunk.STL"
        ]
      }
    }
    HingeJoint {
      jointParameters HingeJointParameters {
        axis 0 0 1
        anchor 0.0625 0 0.243
      }
      device [
        RotationalMotor {
          name "AAHead_yaw"
          maxTorque 10000
        }
        PositionSensor {
          name "AAHead_yaw_sensor"
        }
      ]
      endPoint Solid {
        translation 0.0625 0 0.243
        children [
          Shape {
            appearance DEF H1_material PBRAppearance {
              baseColor 0.4 0.4 0.4
              roughness 1
              metalness 0
            }
            geometry DEF H1 Mesh {
              url [
                "./T1_release_meshes_7Dof/H1.STL"
              ]
            }
          }
          HingeJoint {
            jointParameters HingeJointParameters {
              axis 0 1 0
              anchor 0 0 0.06185
            }
            device [
              RotationalMotor {
                name "Head_pitch"
                maxTorque 10000
              }
              PositionSensor {
                name "Head_pitch_sensor"
              }
            ]
            endPoint Solid {
              translation 0 0 0.06185
              rotation 0 1 0 0
              children [
                Shape {
                  appearance DEF H2_material PBRAppearance {
                    baseColor 0.4 0.4 0.4
                    roughness 1
                    metalness 0
                  }
                  geometry DEF H2 Mesh {
                    url [
                      "./T1_release_meshes_7Dof/H2.STL"
                    ]
                  }
                }
              ]
              name "H2"
              physics Physics {
                density -1
                mass 0.631019
                centerOfMass [
                  0.007802 0.001262 0.098631
                ]
                inertiaMatrix [
                  0.002025 0.00192 0.001739
                  -2.5e-05 4.6e-05 3.6e-05
                ]
              }
            }
          }
        ]
        name "H1"
        physics Physics {
          density -1
          mass 0.44391
          centerOfMass [
            -0.000508 -0.001403 0.057432
          ]
          inertiaMatrix [
            0.000224 0.000241 0.00015
            3e-06 1e-06 -2e-06
          ]
        }
      }
    }




    HingeJoint {
      jointParameters HingeJointParameters {
        axis 0 1 0
        anchor 0.0575 0.1063 0.219
      }
      device [
        RotationalMotor {
          name "Left_Shoulder_Pitch"
          maxTorque 10000
        }
        PositionSensor {
          name "Left_Shoulder_Pitch_sensor"
        }
      ]
      endPoint Solid {
        translation 0.0575 0.1063 0.219
        rotation 0 1 0 0.0008813690977021401
        children [
          Shape {
            appearance DEF AL1_material PBRAppearance {
              baseColor 0.486275 0.486275 0.486275
              roughness 1
              metalness 0
            }
            geometry DEF AL1 Mesh {
              url [
                "./T1_release_meshes_7Dof/AL1.STL"
              ]
            }
          }
          HingeJoint {
            jointParameters HingeJointParameters {
              anchor 0 0.047 0
            }
            device [
              RotationalMotor {
                name "Left_Shoulder_Roll"
                maxTorque 10000
              }
              PositionSensor {
                name "Left_Shoulder_Roll_sensor"
              }
            ]
            endPoint Solid {
              translation 0 0.047 0
              rotation 1 0 0 0
              children [
                Shape {
                  appearance DEF AL2_material PBRAppearance {
                    baseColor 0.486275 0.486275 0.486275
                    roughness 1
                    metalness 0
                  }
                  geometry DEF AL2 Mesh {
                    url [
                      "./T1_release_meshes_7Dof/AL2.STL"
                    ]
                  }
                }
                HingeJoint {
                  jointParameters HingeJointParameters {
                    axis 0 1 0
                    anchor 0.00025 0.0605 0
                  }
                  device [
                    RotationalMotor {
                      name "Left_Elbow_Pitch"
                      maxTorque 10000
                    }
                    PositionSensor {
                      name "Left_Elbow_Pitch_sensor"
                    }
                  ]
                  endPoint Solid {
                    translation 0.00025 0.0605 0
                    rotation 0 1 0 0
                    children [
                      Shape {
                        appearance DEF AL3_material PBRAppearance {
                          baseColor 0.486275 0.486275 0.486275
                          roughness 1
                          metalness 0
                        }
                        geometry DEF AL3 Mesh {
                          url [
                            "./T1_release_meshes_7Dof/AL3.STL"
                          ]
                        }
                      }
                      HingeJoint {
                        jointParameters HingeJointParameters {
                          axis 0 0 1
                          anchor 0 0.1471 0
                        }
                        device [
                          RotationalMotor {
                            name "Left_Elbow_Yaw"
                            maxTorque 10000
                          }
                          PositionSensor {
                            name "Left_Elbow_Yaw_sensor"
                          }
                        ]
                        endPoint Solid {
                          translation 0 0.1471 0
                          children [
                            Shape {
                              appearance DEF AL4_material PBRAppearance {
                                baseColor 0.486275 0.486275 0.486275
                                roughness 1
                                metalness 0
                              }
                              geometry DEF AL4 Mesh {
                                url [
                                  "./T1_release_meshes_7Dof/AL4.STL"
                                ]
                              }
                            }
                            HingeJoint {
                              jointParameters HingeJointParameters {
                                position -4.167587099336564e-08
                                axis 0 1 0
                                anchor 0 0.105 0.00025
                              }
                              device [
                                RotationalMotor {
                                  name "Left_Wrist_Pitch"
                                  maxTorque 10000
                                }
                                PositionSensor {
                                  name "Left_Wrist_Pitch_sensor"
                                }
                              ]
                              endPoint Solid {
                                translation 0 0.105 0.00025
                                rotation 0 1 0 0
                                children [
                                  Shape {
                                    appearance DEF AL5_material PBRAppearance {
                                      baseColor 0.486275 0.486275 0.486275
                                      roughness 1
                                      metalness 0
                                    }
                                    geometry DEF AL5 Mesh {
                                      url [
                                        "./T1_release_meshes_7Dof/AL5.STL"
                                      ]
                                    }
                                  }
                                  HingeJoint {
                                    jointParameters HingeJointParameters {
                                      position 2.3646190490118433e-08
                                      axis 0 0 1
                                      anchor 0 0.042 0
                                    }
                                    device [
                                      RotationalMotor {
                                        name "Left_Wrist_Yaw"
                                        maxTorque 10000
                                      }
                                      PositionSensor {
                                        name "Left_Wrist_Yaw_sensor"
                                      }
                                    ]
                                    endPoint Solid {
                                      translation 0 0.042 0
                                      rotation 0 0 1 0
                                      children [
                                        Shape {
                                          appearance DEF AL6_material PBRAppearance {
                                            baseColor 0.486275 0.486275 0.486275
                                            roughness 1
                                            metalness 0
                                          }
                                          geometry DEF AL6 Mesh {
                                            url [
                                              "./T1_release_meshes_7Dof/AL6.STL"
                                            ]
                                          }
                                        }
                                        HingeJoint {
                                          jointParameters HingeJointParameters {
                                            anchor 0.00475 0.07 0.0015
                                          }
                                          device [
                                            RotationalMotor {
                                              name "Left_Hand_Roll"
                                              maxTorque 10000
                                            }
                                            PositionSensor {
                                              name "Left_Hand_Roll_sensor"
                                            }
                                          ]
                                          endPoint Solid {
                                            translation 0.00475 0.07 0.0015
                                            rotation 1 0 0 0
                                            children [
                                              Shape {
                                                appearance DEF left_hand_link_material PBRAppearance {
                                                  baseColor 0.486275 0.486275 0.486275
                                                  roughness 1
                                                  metalness 0
                                                }
                                                geometry DEF AL7 Mesh {
                                                  url [
                                                    "./T1_release_meshes_7Dof/AL7.STL"
                                                  ]
                                                }
                                              }
                                            ]
                                            name "left_hand_link"
                                            physics Physics {
                                              density -1
                                              mass 0.24875
                                              centerOfMass [
                                                -0.006792 0.06373 0.011867
                                              ]
                                              inertiaMatrix [
                                                0.001568 0.000259 0.001609
                                                -9.4e-05 -1.9e-05 0.000214
                                              ]
                                            }
                                          }
                                        }
                                      ]
                                      name "AL6"
                                      physics Physics {
                                        density -1
                                        mass 0.26532
                                        centerOfMass [
                                          -0.000729 0.056578 -0.005626
                                        ]
                                        inertiaMatrix [
                                          0.001171 0.000166 0.001138
                                          -1.5e-05 -1e-06 -1.5e-05
                                        ]
                                      }
                                    }
                                  }
                                ]
                                name "AL5"
                                physics Physics {
                                  density -1
                                  mass 0.42219
                                  centerOfMass [
                                    -3.8e-05 0.036076 0.005671
                                  ]
                                  inertiaMatrix [
                                    0.000823 0.000216 0.000785
                                    0 0 9.8e-05
                                  ]
                                }
                              }
                            }
                          ]
                          name "AL4"
                          physics Physics {
                            density -1
                            mass 0.2984
                            centerOfMass [
                              -0.000469 0.062372 0.001518
                            ]
                            inertiaMatrix [
                              0.001673 0.000214 0.001608
                              -1.2e-05 0 4e-06
                            ]
                          }
                        }
                      }
                    ]
                    name "AL3"
                    physics Physics {
                      density -1
                      mass 1.02
                      centerOfMass [
                        0 0.085353 -9.9e-05
                      ]
                      inertiaMatrix [
                        0.012869 0.000621 0.012798
                        0 0 -2.4e-05
                      ]
                    }
                  }
                }
              ]
              name "AL2"
              physics Physics {
                density -1
                mass 0.16
                centerOfMass [
                  0.003862 0.037976 0
                ]
                inertiaMatrix [
                  0.000345 0.000177 0.000401
                  8e-06 0 0
                ]
              }
            }
          }
        ]
        name "AL1"
        physics Physics {
          density -1
          mass 0.53
          centerOfMass [
            -0.000677 0.044974 0
          ]
          inertiaMatrix [
            0.001293 0.000293 0.001367
            -1.7e-05 0 0
          ]
        }
      }
    }

    HingeJoint {
      jointParameters HingeJointParameters {
        axis 0 1 0
        anchor 0.0575 -0.1063 0.219
      }
      device [
        RotationalMotor {
          name "Right_Shoulder_Pitch"
          maxTorque 10000
        }
        PositionSensor {
          name "Right_Shoulder_Pitch_sensor"
        }
      ]
      endPoint Solid {
        translation 0.0575 -0.1063 0.219
        rotation 0 1 0 0
        children [
          Shape {
            appearance DEF AR1_material PBRAppearance {
              baseColor 0.486275 0.486275 0.486275
              roughness 1
              metalness 0
            }
            geometry DEF AR1 Mesh {
              url [
                "./T1_release_meshes_7Dof/AR1.STL"
              ]
            }
          }
          HingeJoint {
            jointParameters HingeJointParameters {
              anchor 0 -0.047 0
            }
            device [
              RotationalMotor {
                name "Right_Shoulder_Roll"
                maxTorque 10000
              }
              PositionSensor {
                name "Right_Shoulder_Roll_sensor"
              }
            ]
            endPoint Solid {
              translation 0 -0.047 0
              rotation 1 0 0 0
              children [
                Shape {
                  appearance DEF AR2_material PBRAppearance {
                    baseColor 0.486275 0.486275 0.486275
                    roughness 1
                    metalness 0
                  }
                  geometry DEF AR2 Mesh {
                    url [
                      "./T1_release_meshes_7Dof/AR2.STL"
                    ]
                  }
                }
                HingeJoint {
                  jointParameters HingeJointParameters {
                    axis 0 1 0
                    anchor 0.00025 -0.0605 0
                  }
                  device [
                    RotationalMotor {
                      name "Right_Elbow_Pitch"
                      maxTorque 10000
                    }
                    PositionSensor {
                      name "Right_Elbow_Pitch_sensor"
                    }
                  ]
                  endPoint Solid {
                    translation 0.00025 -0.0605 0
                    rotation 0 1 0 0
                    children [
                      Shape {
                        appearance DEF AR3_material PBRAppearance {
                          baseColor 0.486275 0.486275 0.486275
                          roughness 1
                          metalness 0
                        }
                        geometry DEF AR3 Mesh {
                          url [
                            "./T1_release_meshes_7Dof/AR3.STL"
                          ]
                        }
                      }
                      HingeJoint {
                        jointParameters HingeJointParameters {
                          axis 0 0 1
                          anchor 0 -0.1471 0
                        }
                        device [
                          RotationalMotor {
                            name "Right_Elbow_Yaw"
                            maxTorque 10000
                          }
                          PositionSensor {
                            name "Right_Elbow_Yaw_sensor"
                          }
                        ]
                        endPoint Solid {
                          translation 0 -0.1471 0
                          rotation 0 0 1 0
                          children [
                            Shape {
                              appearance DEF AR4_material PBRAppearance {
                                baseColor 0.486275 0.486275 0.486275
                                roughness 1
                                metalness 0
                              }
                              geometry DEF AR4 Mesh {
                                url [
                                  "./T1_release_meshes_7Dof/AR4.STL"
                                ]
                              }
                            }
                            HingeJoint {
                              jointParameters HingeJointParameters {
                                axis 0 1 0
                                anchor 0 -0.105 0.00025
                              }
                              device [
                                RotationalMotor {
                                  name "Right_Wrist_Pitch"
                                  maxTorque 10000
                                }
                                PositionSensor {
                                  name "Right_Wrist_Pitch_sensor"
                                }
                              ]
                              endPoint Solid {
                                translation 0 -0.105 0.00025
                                rotation 0 1 0 0
                                children [
                                  Shape {
                                    appearance DEF AR5_material PBRAppearance {
                                      baseColor 0.486275 0.486275 0.486275
                                      roughness 1
                                      metalness 0
                                    }
                                    geometry DEF AR5 Mesh {
                                      url [
                                        "./T1_release_meshes_7Dof/AR5.STL"
                                      ]
                                    }
                                  }
                                  HingeJoint {
                                    jointParameters HingeJointParameters {
                                      axis 0 0 1
                                      anchor 0 -0.042 0
                                    }
                                    device [
                                      RotationalMotor {
                                        name "Right_Wrist_Yaw"
                                        maxTorque 10000
                                      }
                                      PositionSensor {
                                        name "Right_Wrist_Yaw_sensor"
                                      }
                                    ]
                                    endPoint Solid {
                                      translation 0 -0.042 0
                                      rotation 0 0 1 0
                                      children [
                                        Shape {
                                          appearance DEF AR6_material PBRAppearance {
                                            baseColor 0.486275 0.486275 0.486275
                                            roughness 1
                                            metalness 0
                                          }
                                          geometry DEF AR6 Mesh {
                                            url [
                                              "./T1_release_meshes_7Dof/AR6.STL"
                                            ]
                                          }
                                        }
                                        HingeJoint {
                                          jointParameters HingeJointParameters {
                                            anchor 0.00475 -0.07 0.0015
                                          }
                                          device [
                                            RotationalMotor {
                                              name "Right_Hand_Roll"
                                              maxTorque 10000
                                            }
                                            PositionSensor {
                                              name "Right_Hand_Roll_sensor"
                                            }
                                          ]
                                          endPoint Solid {
                                            translation 0.00475 -0.07 0.0015
                                            rotation 1 0 0 0
                                            children [
                                              Shape {
                                                appearance DEF right_hand_link_material PBRAppearance {
                                                  baseColor 0.486275 0.486275 0.486275
                                                  roughness 1
                                                  metalness 0
                                                }
                                                geometry DEF AR7 Mesh {
                                                  url [
                                                    "./T1_release_meshes_7Dof/AR7.STL"
                                                  ]
                                                }
                                              }
                                            ]
                                            name "right_hand_link"
                                            physics Physics {
                                              density -1
                                              mass 0.24612
                                              centerOfMass [
                                                -0.004776 -0.064411 0.011992
                                              ]
                                              inertiaMatrix [
                                                0.001568 0.00025 0.0016
                                                8.4e-05 -1.5e-05 -0.000214
                                              ]
                                            }
                                          }
                                        }
                                      ]
                                      name "AR6"
                                      physics Physics {
                                        density -1
                                        mass 0.28215
                                        centerOfMass [
                                          -0.001144 -0.056205 -0.005662
                                        ]
                                        inertiaMatrix [
                                          0.001238 0.000182 0.00121
                                          2.4e-05 -1e-06 1.4e-05
                                        ]
                                      }
                                    }
                                  }
                                ]
                                name "AR5"
                                physics Physics {
                                  density -1
                                  mass 0.43402
                                  centerOfMass [
                                    3.7e-05 -0.035638 0.005315
                                  ]
                                  inertiaMatrix [
                                    0.000836 0.00022 0.000797
                                    0 0 -9.5e-05
                                  ]
                                }
                              }
                            }
                          ]
                          name "AR4"
                          physics Physics {
                            density -1
                            mass 0.3599
                            centerOfMass [
                              -0.000457 -0.067734 0.001747
                            ]
                            inertiaMatrix [
                              0.002292 0.000234 0.002223
                              1.4e-05 0 -5e-06
                            ]
                          }
                        }
                      }
                    ]
                    name "AR3"
                    physics Physics {
                      density -1
                      mass 1.02
                      centerOfMass [
                        0 -0.085353 -9.9e-05
                      ]
                      inertiaMatrix [
                        0.012869 0.000621 0.012798
                        0 0 2.4e-05
                      ]
                    }
                  }
                }
              ]
              name "AR2"
              physics Physics {
                density -1
                mass 0.16
                centerOfMass [
                  0.003862 -0.037976 0
                ]
                inertiaMatrix [
                  0.000345 0.000177 0.000401
                  -8e-06 0 0
                ]
              }
            }
          }
        ]
        name "AR1"
        physics Physics {
          density -1
          mass 0.53
          centerOfMass [
            -0.000677 -0.044974 0
          ]
          inertiaMatrix [
            0.001293 0.000293 0.001367
            -1.7e-05 0 0
          ]
        }
      }
    }



    HingeJoint {
      jointParameters HingeJointParameters {
        axis 0 0 1
        anchor 0.0625 0 -0.1155
      }
      device [
        RotationalMotor {
          name "Waist"
          maxTorque 10000
        }
        PositionSensor {
          name "Waist_sensor"
        }
      ]
      endPoint Solid {
        translation 0.0625 0 -0.1155
        children [
          Shape {
            appearance DEF Waist_material PBRAppearance {
              baseColor 0.4 0.4 0.4
              roughness 1
              metalness 0
            }
            geometry DEF Waist Mesh {
              url [
                "./T1_release_meshes_7Dof/Waist.STL"
              ]
            }
          }
          HingeJoint {
            jointParameters HingeJointParameters {
              axis 0 1 0
              anchor 0 0.106 0
            }
            device [
              RotationalMotor {
                name "Left_Hip_Pitch"
                maxTorque 10000
              }
              PositionSensor {
                name "Left_Hip_Pitch_sensor"
              }
            ]
            endPoint Solid {
              translation 0 0.106 0
              rotation 0 1 0 0
              children [
                Shape {
                  appearance DEF Hip_Pitch_Left_material PBRAppearance {
                    baseColor 0.76 0.76 0.76
                    roughness 1
                    metalness 0
                  }
                  geometry DEF Hip_Pitch_Left Mesh {
                    url [
                      "./T1_release_meshes_7Dof/Hip_Pitch_Left.STL"
                    ]
                  }
                }
                HingeJoint {
                  jointParameters HingeJointParameters {
                    anchor 0 0 -0.02
                  }
                  device [
                    RotationalMotor {
                      name "Left_Hip_Roll"
                      maxTorque 10000
                    }
                    PositionSensor {
                      name "Left_Hip_Roll_sensor"
                    }
                  ]
                  endPoint Solid {
                    translation 0 0 -0.02
                    rotation 1 0 0 0
                    children [
                      Shape {
                        appearance DEF Hip_Roll_Left_material PBRAppearance {
                          baseColor 0.4 0.4 0.4
                          roughness 1
                          metalness 0
                        }
                        geometry DEF Hip_Roll_Left Mesh {
                          url [
                            "./T1_release_meshes_7Dof/Hip_Roll_Left.STL"
                          ]
                        }
                      }
                      HingeJoint {
                        jointParameters HingeJointParameters {
                          axis 0 0 1
                          anchor 0 0 -0.081854
                        }
                        device [
                          RotationalMotor {
                            name "Left_Hip_Yaw"
                            maxTorque 10000
                          }
                          PositionSensor {
                            name "Left_Hip_Yaw_sensor"
                          }
                        ]
                        endPoint Solid {
                          translation 0 0 -0.081854
                          children [
                            Shape {
                              appearance DEF Hip_Yaw_Left_material PBRAppearance {
                                baseColor 0.4 0.4 0.4
                                roughness 1
                                metalness 0
                              }
                              geometry DEF Hip_Yaw_Left Mesh {
                                url [
                                  "./T1_release_meshes_7Dof/Hip_Yaw_Left.STL"
                                ]
                              }
                            }
                            HingeJoint {
                              jointParameters HingeJointParameters {
                                axis 0 1 0
                                anchor -0.014 0 -0.134
                              }
                              device [
                                RotationalMotor {
                                  name "Left_Knee_Pitch"
                                  maxTorque 10000
                                }
                                PositionSensor {
                                  name "Left_Knee_Pitch_sensor"
                                }
                              ]
                              endPoint Solid {
                                translation -0.014 0 -0.134
                                rotation 0 1 0 0
                                children [
                                  Shape {
                                    appearance DEF Shank_Left_material PBRAppearance {
                                      baseColor 0.4 0.4 0.4
                                      roughness 1
                                      metalness 0
                                    }
                                    geometry DEF Shank_Left Mesh {
                                      url [
                                        "./T1_release_meshes_7Dof/Shank_Left.STL"
                                      ]
                                    }
                                  }
                                  HingeJoint {
                                    jointParameters HingeJointParameters {
                                      axis 0 1 0
                                      anchor 0 0 -0.28
                                    }
                                    endPoint Solid {
                                      translation 0 0 -0.28
                                      rotation 0 1 0 0
                                      children [
                                        Shape {
                                          appearance DEF Ankle_Cross_Left_material PBRAppearance {
                                            baseColor 0.4 0.4 0.4
                                            roughness 1
                                            metalness 0
                                          }
                                          geometry DEF Ankle_Cross_Left Mesh {
                                            url [
                                              "./T1_release_meshes_7Dof/Ankle_Cross_Left.STL"
                                            ]
                                          }
                                        }
                                        HingeJoint {
                                          jointParameters HingeJointParameters {
                                            anchor 0 0.00025 -0.012
                                          }
                                          endPoint Solid {
                                            translation 0 0.00025 -0.012
                                            rotation 1 0 0 0
                                            children [
                                              HingeJoint {
                                                jointParameters HingeJointParameters {
                                                  axis 0 1 0
                                                  anchor -0.0415 0.0275 0.0327
                                                  staticFriction 0.05
                                                }
                                                endPoint Solid {
                                                  translation -0.0415 0.0275 0.0327
                                                  rotation 0 1 0 0
                                                  children [
                                                    HingeJoint {
                                                      jointParameters HingeJointParameters {
                                                        axis 0 0 1
                                                        staticFriction 0.05
                                                      }
                                                      endPoint SolidReference {
                                                        solidName "Up_Left_XX_Ball"
                                                      }
                                                    }
                                                  ]
                                                  physics Physics {
                                                    density -1
                                                    mass 0.005
                                                    centerOfMass [
                                                      0 0 0
                                                    ]
                                                    inertiaMatrix [
                                                      1e-05 1e-05 1e-05
                                                      0 0 0
                                                    ]
                                                  }
                                                }
                                              }
                                              HingeJoint {
                                                jointParameters HingeJointParameters {
                                                  axis 0 1 0
                                                  anchor -0.0415 -0.0275 0.0327
                                                  staticFriction 0.05
                                                }
                                                endPoint Solid {
                                                  translation -0.0415 -0.0275 0.0327
                                                  rotation 0 1 0 0
                                                  children [
                                                    HingeJoint {
                                                      jointParameters HingeJointParameters {
                                                        axis 0 0 1
                                                        staticFriction 0.05
                                                      }
                                                      endPoint SolidReference {
                                                        solidName "Down_Left_XX_Ball"
                                                      }
                                                    }
                                                  ]
                                                  name "solid(1)"
                                                  physics Physics {
                                                    density -1
                                                    mass 0.005
                                                    centerOfMass [
                                                      0 0 0
                                                    ]
                                                    inertiaMatrix [
                                                      1e-05 1e-05 1e-05
                                                      0 0 0
                                                    ]
                                                  }
                                                }
                                              }
                                              Shape {
                                                appearance DEF left_foot_link_material PBRAppearance {
                                                  baseColor 0.4 0.4 0.4
                                                  roughness 1
                                                  metalness 0
                                                }
                                                geometry DEF left_foot_link Mesh {
                                                  url [
                                                    "./T1_release_meshes_7Dof/left_foot_link.STL"
                                                  ]
                                                }
                                              }
                                            ]
                                            name "left_foot_link"
                                            boundingObject Pose {
                                              translation 0.010384 0 -0.0155
                                              children [
                                                Box {
                                                  size 0.22487 0.1 0.031
                                                }
                                              ]
                                            }
                                            physics Physics {
                                              density -1
                                              mass 0.685
                                              centerOfMass [
                                                -0.000249 0 -0.00914
                                              ]
                                              inertiaMatrix [
                                                0.000738 0.002385 0.002671
                                                0 -0.000147 0
                                              ]
                                            }
                                          }
                                        }
                                      ]
                                      name "Ankle_Cross_Left"
                                      physics Physics {
                                        density -1
                                        mass 0.073
                                        centerOfMass [
                                          -0.003722 0 -0.007981
                                        ]
                                        inertiaMatrix [
                                          1.2e-05 2.9e-05 2.5e-05
                                          0 3e-06 0
                                        ]
                                      }
                                    }
                                  }
                                  HingeJoint {
                                    jointParameters HingeJointParameters {
                                      axis 0 1 0
                                      anchor -0.014 0.02775 -0.096
                                    }
                                    device [
                                      RotationalMotor {
                                        name "Crank_Up_Left"
                                        maxTorque 10000
                                      }
                                      PositionSensor {
                                        name "Crank_Up_Left_sensor"
                                      }
                                    ]
                                    endPoint Solid {
                                      translation -0.014 0.02775 -0.096
                                      rotation 0 1 0 0
                                      children [
                                        Shape {
                                          appearance DEF Crank_Up_Left_material PBRAppearance {
                                            baseColor 0.752941 0.752941 0.752941
                                            roughness 1
                                            metalness 0
                                          }
                                          geometry DEF Crank_Up_Left Mesh {
                                            url [
                                              "./T1_release_meshes_7Dof/Crank_Up_Left.STL"
                                            ]
                                          }
                                        }
                                        HingeJoint {
                                          jointParameters HingeJointParameters {
                                            anchor 0.042936 0 0.002347
                                          }
                                          endPoint Solid {
                                            translation 0.042936 0 0.002347
                                            rotation 1 0 0 0
                                            children [
                                              Shape {
                                                appearance DEF Up_Left_X_Ball_material PBRAppearance {
                                                  baseColor 0.752941 0.752941 0.752941
                                                  roughness 1
                                                  metalness 0
                                                }
                                                geometry DEF Up_Left_X_Ball Mesh {
                                                  url [
                                                    "./T1_release_meshes_7Dof/Up_Left_X_Ball.STL"
                                                  ]
                                                }
                                              }
                                              HingeJoint {
                                                jointParameters HingeJointParameters {
                                                  axis 0 1 0
                                                }
                                                endPoint Solid {
                                                  rotation 0 1 0 0
                                                  children [
                                                    Shape {
                                                      appearance DEF Up_Left_Y_Ball_material PBRAppearance {
                                                        baseColor 0.752941 0.752941 0.752941
                                                        roughness 1
                                                        metalness 0
                                                      }
                                                      geometry DEF Up_Left_Y_Ball Mesh {
                                                        url [
                                                          "./T1_release_meshes_7Dof/Up_Left_Y_Ball.STL"
                                                        ]
                                                      }
                                                    }
                                                    HingeJoint {
                                                      jointParameters HingeJointParameters {
                                                        axis 0 0 1
                                                      }
                                                      endPoint Solid {
                                                        children [
                                                          Shape {
                                                            appearance DEF Link_Long_Left_material PBRAppearance {
                                                              baseColor 0.752941 0.752941 0.752941
                                                              roughness 1
                                                              metalness 0
                                                            }
                                                            geometry DEF Link_Long_Left Mesh {
                                                              url [
                                                                "./T1_release_meshes_7Dof/Link_Long_Left.STL"
                                                              ]
                                                            }
                                                          }
                                                          HingeJoint {
                                                            jointParameters HingeJointParameters {
                                                              anchor -0.070436 0 -0.16565
                                                            }
                                                            endPoint Solid {
                                                              translation -0.070436 0 -0.16565
                                                              rotation 1 0 0 0
                                                              children [
                                                                Shape {
                                                                  appearance DEF Up_Left_XX_Ball_material PBRAppearance {
                                                                    baseColor 0.752941 0.752941 0.752941
                                                                    roughness 1
                                                                    metalness 0
                                                                  }
                                                                  geometry DEF Up_Left_XX_Ball Mesh {
                                                                    url [
                                                                      "./T1_release_meshes_7Dof/Up_Left_XX_Ball.STL"
                                                                    ]
                                                                  }
                                                                }
                                                              ]
                                                              name "Up_Left_XX_Ball"
                                                              physics Physics {
                                                                density -1
                                                                mass 0.001
                                                                centerOfMass [
                                                                  0 0 0
                                                                ]
                                                                inertiaMatrix [
                                                                  4.071504e-10 4.071504e-10 4.071504e-10
                                                                  -4.591775e-41 2.039158e-56 -2.295887e-41
                                                                ]
                                                              }
                                                            }
                                                          }
                                                        ]
                                                        name "Link_Long_Left"
                                                        physics Physics {
                                                          density -1
                                                          mass 0.057
                                                          centerOfMass [
                                                            -0.023162 0 -0.08712
                                                          ]
                                                          inertiaMatrix [
                                                            0.000632 0.000707 7.6e-05
                                                            0 0.000201 0
                                                          ]
                                                        }
                                                      }
                                                    }
                                                  ]
                                                  name "Up_Left_Y_Ball"
                                                  physics Physics {
                                                    density -1
                                                    mass 0.001
                                                    centerOfMass [
                                                      0 0 0
                                                    ]
                                                    inertiaMatrix [
                                                      4.071504e-10 4.071504e-10 4.071504e-10
                                                      0 -1.019579e-56 -2.295887e-41
                                                    ]
                                                  }
                                                }
                                              }
                                            ]
                                            name "Up_Left_X_Ball"
                                            physics Physics {
                                              density -1
                                              mass 0.001
                                              centerOfMass [
                                                0 0 0
                                              ]
                                              inertiaMatrix [
                                                4.071504e-10 4.071504e-10 4.071504e-10
                                                0 -1.019579e-56 -2.295887e-41
                                              ]
                                            }
                                          }
                                        }
                                      ]
                                      name "Crank_Up_Left"
                                      physics Physics {
                                        density -1
                                        mass 0.0395
                                        centerOfMass [
                                          0.015723 0.006606 0.000859
                                        ]
                                        inertiaMatrix [
                                          5e-06 2.9e-05 2.8e-05
                                          3e-06 1e-06 0
                                        ]
                                      }
                                    }
                                  }
                                  HingeJoint {
                                    jointParameters HingeJointParameters {
                                      axis 0 1 0
                                      anchor -0.014 -0.02725 -0.156
                                    }
                                    device [
                                      RotationalMotor {
                                        name "Crank_Down_Left"
                                        maxTorque 10000
                                      }
                                      PositionSensor {
                                        name "Crank_Down_Left_sensor"
                                      }
                                    ]
                                    endPoint Solid {
                                      translation -0.014 -0.02725 -0.156
                                      rotation 0 1 0 0
                                      children [
                                        Shape {
                                          appearance DEF Crank_Down_Left_material PBRAppearance {
                                            baseColor 0.752941 0.752941 0.752941
                                            roughness 1
                                            metalness 0
                                          }
                                          geometry DEF Crank_Down_Left Mesh {
                                            url [
                                              "./T1_release_meshes_7Dof/Crank_Down_Left.STL"
                                            ]
                                          }
                                        }
                                        HingeJoint {
                                          jointParameters HingeJointParameters {
                                            anchor 0.042593 0 -0.005899
                                          }
                                          endPoint Solid {
                                            translation 0.042593 0 -0.005899
                                            rotation 1 0 0 0
                                            children [
                                              Shape {
                                                appearance DEF Down_Left_X_Ball_material PBRAppearance {
                                                  baseColor 0.752941 0.752941 0.752941
                                                  roughness 1
                                                  metalness 0
                                                }
                                                geometry DEF Down_Left_X_Ball Mesh {
                                                  url [
                                                    "./T1_release_meshes_7Dof/Down_Left_X_Ball.STL"
                                                  ]
                                                }
                                              }
                                              HingeJoint {
                                                jointParameters HingeJointParameters {
                                                  axis 0 1 0
                                                }
                                                endPoint Solid {
                                                  rotation 0 1 0 0
                                                  children [
                                                    Shape {
                                                      appearance DEF Down_Left_Y_Ball_material PBRAppearance {
                                                        baseColor 0.752941 0.752941 0.752941
                                                        roughness 1
                                                        metalness 0
                                                      }
                                                      geometry DEF Down_Left_Y_Ball Mesh {
                                                        url [
                                                          "./T1_release_meshes_7Dof/Down_Left_Y_Ball.STL"
                                                        ]
                                                      }
                                                    }
                                                    HingeJoint {
                                                      jointParameters HingeJointParameters {
                                                        axis 0 0 1
                                                      }
                                                      endPoint Solid {
                                                        children [
                                                          Shape {
                                                            appearance DEF Link_Short_Left_material PBRAppearance {
                                                              baseColor 0.752941 0.752941 0.752941
                                                              roughness 1
                                                              metalness 0
                                                            }
                                                            geometry DEF Link_Short_Left Mesh {
                                                              url [
                                                                "./T1_release_meshes_7Dof/Link_Short_Left.STL"
                                                              ]
                                                            }
                                                          }
                                                          HingeJoint {
                                                            jointParameters HingeJointParameters {
                                                              anchor -0.070093 0 -0.097401
                                                            }
                                                            endPoint Solid {
                                                              translation -0.070093 0 -0.097401
                                                              rotation 1 0 0 0
                                                              children [
                                                                Shape {
                                                                  appearance DEF Down_Left_XX_Ball_material PBRAppearance {
                                                                    baseColor 0.752941 0.752941 0.752941
                                                                    roughness 1
                                                                    metalness 0
                                                                  }
                                                                  geometry DEF Down_Left_XX_Ball Mesh {
                                                                    url [
                                                                      "./T1_release_meshes_7Dof/Down_Left_XX_Ball.STL"
                                                                    ]
                                                                  }
                                                                }
                                                              ]
                                                              name "Down_Left_XX_Ball"
                                                              physics Physics {
                                                                density -1
                                                                mass 0.001
                                                                centerOfMass [
                                                                  0 0 0
                                                                ]
                                                                inertiaMatrix [
                                                                  4.071504e-10 4.071504e-10 4.071504e-10
                                                                  -4.591775e-41 2.039158e-56 -2.295887e-41
                                                                ]
                                                              }
                                                            }
                                                          }
                                                        ]
                                                        name "Link_Short_Left"
                                                        physics Physics {
                                                          density -1
                                                          mass 0.04
                                                          centerOfMass [
                                                            -0.031486 0 -0.050737
                                                          ]
                                                          inertiaMatrix [
                                                            0.000158 0.000229 7.1e-05
                                                            0 0.000104 0
                                                          ]
                                                        }
                                                      }
                                                    }
                                                  ]
                                                  name "Down_Left_Y_Ball"
                                                  physics Physics {
                                                    density -1
                                                    mass 0.001
                                                    centerOfMass [
                                                      0 0 0
                                                    ]
                                                    inertiaMatrix [
                                                      4.071504e-10 4.071504e-10 4.071504e-10
                                                      5.739719e-42 -6.372368e-58 -2.869859e-42
                                                    ]
                                                  }
                                                }
                                              }
                                            ]
                                            name "Down_Left_X_Ball"
                                            physics Physics {
                                              density -1
                                              mass 0.001
                                              centerOfMass [
                                                0 0 0
                                              ]
                                              inertiaMatrix [
                                                4.071504e-10 4.071504e-10 4.071504e-10
                                                5.739719e-42 -6.372368e-58 -2.869859e-42
                                              ]
                                            }
                                          }
                                        }
                                      ]
                                      name "Crank_Down_Left"
                                      physics Physics {
                                        density -1
                                        mass 0.0395
                                        centerOfMass [
                                          0.015597 -0.006606 -0.00216
                                        ]
                                        inertiaMatrix [
                                          5e-06 2.9e-05 2.8e-05
                                          -3e-06 -2e-06 0
                                        ]
                                      }
                                    }
                                  }
                                ]
                                name "Shank_Left"
                                physics Physics {
                                  density -1
                                  mass 1.62
                                  centerOfMass [
                                    -0.006695 0.000835 -0.119291
                                  ]
                                  inertiaMatrix [
                                    0.029609 0.029555 0.00172
                                    0 0.00148 3.2e-05
                                  ]
                                }
                              }
                            }
                          ]
                          name "Hip_Yaw_Left"
                          physics Physics {
                            density -1
                            mass 2.166
                            centerOfMass [
                              -0.007233 0.000206 -0.089184
                            ]
                            inertiaMatrix [
                              0.025108 0.025733 0.002787
                              -7e-06 0.002094 -5e-05
                            ]
                          }
                        }
                      }
                    ]
                    name "Hip_Roll_Left"
                    physics Physics {
                      density -1
                      mass 0.385
                      centerOfMass [
                        0.001101 2.4e-05 -0.05375
                      ]
                      inertiaMatrix [
                        0.001517 0.001743 0.000515
                        0 1.7e-05 0
                      ]
                    }
                  }
                }
              ]
              name "Hip_Pitch_Left"
              physics Physics {
                density -1
                mass 1.021
                centerOfMass [
                  0.000534 -0.007296 -0.018083
                ]
                inertiaMatrix [
                  0.001805 0.001421 0.001292
                  6e-06 -1.5e-05 8e-05
                ]
              }
            }
          }
          HingeJoint {
            jointParameters HingeJointParameters {
              axis 0 1 0
              anchor 0 -0.106 0
            }
            device [
              RotationalMotor {
                name "Right_Hip_Pitch"
                maxTorque 10000
              }
              PositionSensor {
                name "Right_Hip_Pitch_sensor"
              }
            ]
            endPoint Solid {
              translation 0 -0.106 0
              rotation 0 1 0 0
              children [
                Shape {
                  appearance DEF Hip_Pitch_Right_material PBRAppearance {
                    baseColor 0.76 0.76 0.76
                    roughness 1
                    metalness 0
                  }
                  geometry DEF Hip_Pitch_Right Mesh {
                    url [
                      "./T1_release_meshes_7Dof/Hip_Pitch_Right.STL"
                    ]
                  }
                }
                HingeJoint {
                  jointParameters HingeJointParameters {
                    anchor 0 0 -0.02
                  }
                  device [
                    RotationalMotor {
                      name "Right_Hip_Roll"
                      maxTorque 10000
                    }
                    PositionSensor {
                      name "Right_Hip_Roll_sensor"
                    }
                  ]
                  endPoint Solid {
                    translation 0 0 -0.02
                    rotation 1 0 0 0
                    children [
                      Shape {
                        appearance DEF Hip_Roll_Right_material PBRAppearance {
                          baseColor 0.4 0.4 0.4
                          roughness 1
                          metalness 0
                        }
                        geometry DEF Hip_Roll_Right Mesh {
                          url [
                            "./T1_release_meshes_7Dof/Hip_Roll_Right.STL"
                          ]
                        }
                      }
                      HingeJoint {
                        jointParameters HingeJointParameters {
                          axis 0 0 1
                          anchor 0 0 -0.081854
                        }
                        device [
                          RotationalMotor {
                            name "Right_Hip_Yaw"
                            maxTorque 10000
                          }
                          PositionSensor {
                            name "Right_Hip_Yaw_sensor"
                          }
                        ]
                        endPoint Solid {
                          translation 0 0 -0.081854
                          children [
                            Shape {
                              appearance DEF Hip_Yaw_Right_material PBRAppearance {
                                baseColor 0.4 0.4 0.4
                                roughness 1
                                metalness 0
                              }
                              geometry DEF Hip_Yaw_Right Mesh {
                                url [
                                  "./T1_release_meshes_7Dof/Hip_Yaw_Right.STL"
                                ]
                              }
                            }
                            HingeJoint {
                              jointParameters HingeJointParameters {
                                axis 0 1 0
                                anchor -0.014 0 -0.134
                              }
                              device [
                                RotationalMotor {
                                  name "Right_Knee_Pitch"
                                  maxTorque 10000
                                }
                                PositionSensor {
                                  name "Right_Knee_Pitch_sensor"
                                }
                              ]
                              endPoint Solid {
                                translation -0.014 0 -0.134
                                rotation 0 1 0 0
                                children [
                                  Shape {
                                    appearance DEF Shank_Right_material PBRAppearance {
                                      baseColor 0.4 0.4 0.4
                                      roughness 1
                                      metalness 0
                                    }
                                    geometry DEF Shank_Right Mesh {
                                      url [
                                        "./T1_release_meshes_7Dof/Shank_Right.STL"
                                      ]
                                    }
                                  }
                                  HingeJoint {
                                    jointParameters HingeJointParameters {
                                      axis 0 1 0
                                      anchor 0 0 -0.28
                                    }
                                    endPoint Solid {
                                      translation 0 0 -0.28
                                      rotation 0 1 0 0
                                      children [
                                        Shape {
                                          appearance DEF Ankle_Cross_Right_material PBRAppearance {
                                            baseColor 0.4 0.4 0.4
                                            roughness 1
                                            metalness 0
                                          }
                                          geometry DEF Ankle_Cross_Right Mesh {
                                            url [
                                              "./T1_release_meshes_7Dof/Ankle_Cross_Right.STL"
                                            ]
                                          }
                                        }
                                        HingeJoint {
                                          jointParameters HingeJointParameters {
                                            anchor 0 -0.00025 -0.012
                                          }
                                          endPoint Solid {
                                            translation 0 -0.00025 -0.012
                                            rotation 1 0 0 0
                                            children [
                                              HingeJoint {
                                                jointParameters HingeJointParameters {
                                                  axis 0 1 0
                                                  anchor -0.0415 0.0275 0.0327
                                                  staticFriction 0.05
                                                }
                                                endPoint Solid {
                                                  translation -0.0415 0.0275 0.0327
                                                  rotation 0 1 0 0
                                                  children [
                                                    HingeJoint {
                                                      jointParameters HingeJointParameters {
                                                        axis 0 0 1
                                                        staticFriction 0.05
                                                      }
                                                      endPoint SolidReference {
                                                        solidName "Down_Right_XX_Ball"
                                                      }
                                                    }
                                                  ]
                                                  physics Physics {
                                                    density -1
                                                    mass 0.005
                                                    centerOfMass [
                                                      0 0 0
                                                    ]
                                                    inertiaMatrix [
                                                      1e-05 1e-05 1e-05
                                                      0 0 0
                                                    ]
                                                  }
                                                }
                                              }
                                              HingeJoint {
                                                jointParameters HingeJointParameters {
                                                  axis 0 1 0
                                                  anchor -0.0415 -0.0275 0.0327
                                                  staticFriction 0.05
                                                }
                                                endPoint Solid {
                                                  translation -0.0415 -0.0275 0.0327
                                                  rotation 0 1 0 0
                                                  children [
                                                    HingeJoint {
                                                      jointParameters HingeJointParameters {
                                                        axis 0 0 1
                                                        staticFriction 0.05
                                                      }
                                                      endPoint SolidReference {
                                                        solidName "Up_Right_XX_Ball"
                                                      }
                                                    }
                                                  ]
                                                  name "solid(1)"
                                                  physics Physics {
                                                    density -1
                                                    mass 0.005
                                                    centerOfMass [
                                                      0 0 0
                                                    ]
                                                    inertiaMatrix [
                                                      1e-05 1e-05 1e-05
                                                      0 0 0
                                                    ]
                                                  }
                                                }
                                              }
                                              Shape {
                                                appearance DEF right_foot_link_material PBRAppearance {
                                                  baseColor 0.4 0.4 0.4
                                                  roughness 1
                                                  metalness 0
                                                }
                                                geometry DEF right_foot_link Mesh {
                                                  url [
                                                    "./T1_release_meshes_7Dof/right_foot_link.STL"
                                                  ]
                                                }
                                              }
                                            ]
                                            name "right_foot_link"
                                            boundingObject Pose {
                                              translation 0.010384 0 -0.0155
                                              children [
                                                Box {
                                                  size 0.22487 0.1 0.031
                                                }
                                              ]
                                            }
                                            physics Physics {
                                              density -1
                                              mass 0.685
                                              centerOfMass [
                                                -0.000248 0 -0.00914
                                              ]
                                              inertiaMatrix [
                                                0.000738 0.002385 0.002671
                                                0 -0.000147 0
                                              ]
                                            }
                                          }
                                        }
                                      ]
                                      name "Ankle_Cross_Right"
                                      physics Physics {
                                        density -1
                                        mass 0.073
                                        centerOfMass [
                                          -0.003722 0 -0.007981
                                        ]
                                        inertiaMatrix [
                                          1.2e-05 2.9e-05 2.5e-05
                                          0 3e-06 0
                                        ]
                                      }
                                    }
                                  }
                                  HingeJoint {
                                    jointParameters HingeJointParameters {
                                      axis 0 1 0
                                      anchor -0.014 -0.02775 -0.096
                                    }
                                    device [
                                      RotationalMotor {
                                        name "Crank_Up_Right"
                                        maxTorque 10000
                                      }
                                      PositionSensor {
                                        name "Crank_Up_Right_sensor"
                                      }
                                    ]
                                    endPoint Solid {
                                      translation -0.014 -0.02775 -0.096
                                      rotation 0 1 0 0
                                      children [
                                        Shape {
                                          appearance DEF Crank_Up_Right_material PBRAppearance {
                                            baseColor 0.752941 0.752941 0.752941
                                            roughness 1
                                            metalness 0
                                          }
                                          geometry DEF Crank_Up_Right Mesh {
                                            url [
                                              "./T1_release_meshes_7Dof/Crank_Up_Right.STL"
                                            ]
                                          }
                                        }
                                        HingeJoint {
                                          jointParameters HingeJointParameters {
                                            anchor 0.042936 0 0.002347
                                          }
                                          endPoint Solid {
                                            translation 0.042936 0 0.002347
                                            rotation 1 0 0 0
                                            children [
                                              Shape {
                                                appearance DEF Up_Right_X_Ball_material PBRAppearance {
                                                  baseColor 0.752941 0.752941 0.752941
                                                  roughness 1
                                                  metalness 0
                                                }
                                                geometry DEF Up_Right_X_Ball Mesh {
                                                  url [
                                                    "./T1_release_meshes_7Dof/Up_Right_X_Ball.STL"
                                                  ]
                                                }
                                              }
                                              HingeJoint {
                                                jointParameters HingeJointParameters {
                                                  axis 0 1 0
                                                }
                                                endPoint Solid {
                                                  rotation 0 1 0 0
                                                  children [
                                                    Shape {
                                                      appearance DEF Up_Right_Y_Ball_material PBRAppearance {
                                                        baseColor 0.752941 0.752941 0.752941
                                                        roughness 1
                                                        metalness 0
                                                      }
                                                      geometry DEF Up_Right_Y_Ball Mesh {
                                                        url [
                                                          "./T1_release_meshes_7Dof/Up_Right_Y_Ball.STL"
                                                        ]
                                                      }
                                                    }
                                                    HingeJoint {
                                                      jointParameters HingeJointParameters {
                                                        axis 0 0 1
                                                      }
                                                      endPoint Solid {
                                                        children [
                                                          Shape {
                                                            appearance DEF Link_Long_Right_material PBRAppearance {
                                                              baseColor 0.752941 0.752941 0.752941
                                                              roughness 1
                                                              metalness 0
                                                            }
                                                            geometry DEF Link_Long_Right Mesh {
                                                              url [
                                                                "./T1_release_meshes_7Dof/Link_Long_Right.STL"
                                                              ]
                                                            }
                                                          }
                                                          HingeJoint {
                                                            jointParameters HingeJointParameters {
                                                              anchor -0.070436 0 -0.16565
                                                            }
                                                            endPoint Solid {
                                                              translation -0.070436 0 -0.16565
                                                              rotation 1 0 0 0
                                                              children [
                                                                Shape {
                                                                  appearance DEF Up_Right_XX_Ball_material PBRAppearance {
                                                                    baseColor 0.752941 0.752941 0.752941
                                                                    roughness 1
                                                                    metalness 0
                                                                  }
                                                                  geometry DEF Up_Right_XX_Ball Mesh {
                                                                    url [
                                                                      "./T1_release_meshes_7Dof/Up_Right_XX_Ball.STL"
                                                                    ]
                                                                  }
                                                                }
                                                              ]
                                                              name "Up_Right_XX_Ball"
                                                              physics Physics {
                                                                density -1
                                                                mass 0.001
                                                                centerOfMass [
                                                                  0 0 0
                                                                ]
                                                                inertiaMatrix [
                                                                  4.071504e-10 4.071504e-10 4.071504e-10
                                                                  -4.591775e-41 2.039158e-56 -2.295887e-41
                                                                ]
                                                              }
                                                            }
                                                          }
                                                        ]
                                                        name "Link_Long_Right"
                                                        physics Physics {
                                                          density -1
                                                          mass 0.0565
                                                          centerOfMass [
                                                            -0.023162 0 -0.08712
                                                          ]
                                                          inertiaMatrix [
                                                            0.000632 0.000707 7.6e-05
                                                            0 0.000201 0
                                                          ]
                                                        }
                                                      }
                                                    }
                                                  ]
                                                  name "Up_Right_Y_Ball"
                                                  physics Physics {
                                                    density -1
                                                    mass 0.001
                                                    centerOfMass [
                                                      0 0 0
                                                    ]
                                                    inertiaMatrix [
                                                      4.071504e-10 4.071504e-10 4.071504e-10
                                                      0 -1.019579e-56 -2.295887e-41
                                                    ]
                                                  }
                                                }
                                              }
                                            ]
                                            name "Up_Right_X_Ball"
                                            physics Physics {
                                              density -1
                                              mass 0.001
                                              centerOfMass [
                                                0 0 0
                                              ]
                                              inertiaMatrix [
                                                4.071504e-10 4.071504e-10 4.071504e-10
                                                0 -1.019579e-56 -2.295887e-41
                                              ]
                                            }
                                          }
                                        }
                                      ]
                                      name "Crank_Up_Right"
                                      physics Physics {
                                        density -1
                                        mass 0.04
                                        centerOfMass [
                                          0.015723 -0.006606 0.000859
                                        ]
                                        inertiaMatrix [
                                          5e-06 2.9e-05 2.8e-05
                                          -3e-06 1e-06 0
                                        ]
                                      }
                                    }
                                  }
                                  HingeJoint {
                                    jointParameters HingeJointParameters {
                                      axis 0 1 0
                                      anchor -0.014 0.02725 -0.156
                                    }
                                    device [
                                      RotationalMotor {
                                        name "Crank_Down_Right"
                                        maxTorque 10000
                                      }
                                      PositionSensor {
                                        name "Crank_Down_Right_sensor"
                                      }
                                    ]
                                    endPoint Solid {
                                      translation -0.014 0.02725 -0.156
                                      rotation 0 1 0 0
                                      children [
                                        Shape {
                                          appearance DEF Crank_Down_Right_material PBRAppearance {
                                            baseColor 0.752941 0.752941 0.752941
                                            roughness 1
                                            metalness 0
                                          }
                                          geometry DEF Crank_Down_Right Mesh {
                                            url [
                                              "./T1_release_meshes_7Dof/Crank_Down_Right.STL"
                                            ]
                                          }
                                        }
                                        HingeJoint {
                                          jointParameters HingeJointParameters {
                                            anchor 0.042593 0 -0.005899
                                          }
                                          endPoint Solid {
                                            translation 0.042593 0 -0.005899
                                            rotation 1 0 0 0
                                            children [
                                              Shape {
                                                appearance DEF Down_Right_X_Ball_material PBRAppearance {
                                                  baseColor 0.752941 0.752941 0.752941
                                                  roughness 1
                                                  metalness 0
                                                }
                                                geometry DEF Down_Right_X_Ball Mesh {
                                                  url [
                                                    "./T1_release_meshes_7Dof/Down_Right_X_Ball.STL"
                                                  ]
                                                }
                                              }
                                              HingeJoint {
                                                jointParameters HingeJointParameters {
                                                  axis 0 1 0
                                                }
                                                endPoint Solid {
                                                  rotation 0 1 0 0
                                                  children [
                                                    Shape {
                                                      appearance DEF Down_Right_Y_Ball_material PBRAppearance {
                                                        baseColor 0.752941 0.752941 0.752941
                                                        roughness 1
                                                        metalness 0
                                                      }
                                                      geometry DEF Down_Right_Y_Ball Mesh {
                                                        url [
                                                          "./T1_release_meshes_7Dof/Down_Right_Y_Ball.STL"
                                                        ]
                                                      }
                                                    }
                                                    HingeJoint {
                                                      jointParameters HingeJointParameters {
                                                        axis 0 0 1
                                                      }
                                                      endPoint Solid {
                                                        children [
                                                          Shape {
                                                            appearance DEF Link_Short_Right_material PBRAppearance {
                                                              baseColor 0.752941 0.752941 0.752941
                                                              roughness 1
                                                              metalness 0
                                                            }
                                                            geometry DEF Link_Short_Right Mesh {
                                                              url [
                                                                "./T1_release_meshes_7Dof/Link_Short_Right.STL"
                                                              ]
                                                            }
                                                          }
                                                          HingeJoint {
                                                            jointParameters HingeJointParameters {
                                                              anchor -0.070093 0 -0.097401
                                                            }
                                                            endPoint Solid {
                                                              translation -0.070093 0 -0.097401
                                                              rotation 1 0 0 0
                                                              children [
                                                                Shape {
                                                                  appearance DEF Down_Right_XX_Ball_material PBRAppearance {
                                                                    baseColor 0.752941 0.752941 0.752941
                                                                    roughness 1
                                                                    metalness 0
                                                                  }
                                                                  geometry DEF Down_Right_XX_Ball Mesh {
                                                                    url [
                                                                      "./T1_release_meshes_7Dof/Down_Right_XX_Ball.STL"
                                                                    ]
                                                                  }
                                                                }
                                                              ]
                                                              name "Down_Right_XX_Ball"
                                                              physics Physics {
                                                                density -1
                                                                mass 0.001
                                                                centerOfMass [
                                                                  0 0 0
                                                                ]
                                                                inertiaMatrix [
                                                                  4.071504e-10 4.071504e-10 4.071504e-10
                                                                  -4.591775e-41 2.039158e-56 -2.295887e-41
                                                                ]
                                                              }
                                                            }
                                                          }
                                                        ]
                                                        name "Link_Short_Right"
                                                        physics Physics {
                                                          density -1
                                                          mass 0.04
                                                          centerOfMass [
                                                            -0.031486 0 -0.050737
                                                          ]
                                                          inertiaMatrix [
                                                            0.000158 0.000229 7.1e-05
                                                            0 0.000104 0
                                                          ]
                                                        }
                                                      }
                                                    }
                                                  ]
                                                  name "Down_Right_Y_Ball"
                                                  physics Physics {
                                                    density -1
                                                    mass 0.001
                                                    centerOfMass [
                                                      0 0 0
                                                    ]
                                                    inertiaMatrix [
                                                      4.071504e-10 4.071504e-10 4.071504e-10
                                                      5.739719e-42 -6.372368e-58 -2.869859e-42
                                                    ]
                                                  }
                                                }
                                              }
                                            ]
                                            name "Down_Right_X_Ball"
                                            physics Physics {
                                              density -1
                                              mass 0.001
                                              centerOfMass [
                                                0 0 0
                                              ]
                                              inertiaMatrix [
                                                4.071504e-10 4.071504e-10 4.071504e-10
                                                5.739719e-42 -6.372368e-58 -2.869859e-42
                                              ]
                                            }
                                          }
                                        }
                                      ]
                                      name "Crank_Down_Right"
                                      physics Physics {
                                        density -1
                                        mass 0.04
                                        centerOfMass [
                                          0.015597 0.006606 -0.00216
                                        ]
                                        inertiaMatrix [
                                          5e-06 2.9e-05 2.8e-05
                                          3e-06 -3e-06 0
                                        ]
                                      }
                                    }
                                  }
                                ]
                                name "Shank_Right"
                                physics Physics {
                                  density -1
                                  mass 1.62
                                  centerOfMass [
                                    -0.006574 -0.000315 -0.118161
                                  ]
                                  inertiaMatrix [
                                    0.029681 0.029596 0.001763
                                    4e-06 0.001479 -5e-05
                                  ]
                                }
                              }
                            }
                          ]
                          name "Hip_Yaw_Right"
                          physics Physics {
                            density -1
                            mass 2.17
                            centerOfMass [
                              -0.007191 -0.000149 -0.08922
                            ]
                            inertiaMatrix [
                              0.025137 0.025762 0.002787
                              6e-06 0.002086 4.4e-05
                            ]
                          }
                        }
                      }
                    ]
                    name "Hip_Roll_Right"
                    physics Physics {
                      density -1
                      mass 0.385
                      centerOfMass [
                        0.001099 2.4e-05 -0.053748
                      ]
                      inertiaMatrix [
                        0.001517 0.001743 0.000515
                        0 1.7e-05 0
                      ]
                    }
                  }
                }
              ]
              name "Hip_Pitch_Right"
              physics Physics {
                density -1
                mass 1.021
                centerOfMass [
                  0.000534 0.007514 -0.018082
                ]
                inertiaMatrix [
                  0.001805 0.001421 0.001292
                  -8e-06 -1.5e-05 -8.5e-05
                ]
              }
            }
          }
        ]
        name "Waist"
        physics Physics {
          density -1
          mass 2.581
          centerOfMass [
            0.002284 3e-06 0.007301
          ]
          inertiaMatrix [
            0.005289 0.005299 0.004821
            0 0.000207 1e-06
          ]
        }
      }
    }
  ]
  name "T1_release"
  physics Physics {
    density -1
    mass 11.7
    centerOfMass [
      0.055137 -1e-06 0.105062
    ]
    inertiaMatrix [
      0.09152872 0.07677872 0.05561711
      -4.253697e-07 0.0006463604 5.8234e-07
    ]
  }
  controller "<extern>"
  supervisor TRUE
}
DEF origin Pose {
  children [
    Shape {
      appearance PBRAppearance {
        baseColor 0.937255 0.160784 0.160784
      }
      geometry Box {
        size 0.03 0.03 0.03
      }
    }
  ]
}
